Workbook

Sheet SIV DNA
G1: SIV DNA Sorted CD4+ memory T cells (10^6) before ART stop
A2: Study | B2: Study Code | C2: Study Wk | D2: Animal | E2: ID | F2: Treatment | G2: PBMC | H2: LNMC | I2: GMMC
A3: 1 | B3: 13-03 | C3: 83 | D3: 156-08 | E3: 1 | F3: TLR7 | G3: 1205.3 | H3: 650.4 | I3: 3
A4: 1 | B4: 13-03 | C4: 83 | D4: 166-08 | E4: 2 | F4: TLR7 | G4: 1436.455 | H4: 1050.5 | I4: 3
A5: 1 | B5: 13-03 | C5: 83 | D5: 280-09 | E5: 3 | F5: TLR7 | G5: 1174.3 | H5: 1586.4 | I5: 3
A6: 1 | B6: 13-03 | C6: 83 | D6: 310-09 | E6: 4 | F6: TLR7 | G6: 2457.584 | H6: 1163.3 | I6: 3
A7: 1 | B7: 13-03 | C7: 83 | D7: 205-08 | E7: 5 | F7: Control | G7: 1107.235 | H7: 1003.2 | I7: 595
A8: 1 | B8: 13-03 | C8: 83 | D8: 267-08 | E8: 6 | F8: Control | G8: 8622.721 | H8: 2506.208 | I8: 596
A9: 1 | B9: 13-03 | C9: 83 | D9: 105-09 | E9: 7 | F9: Control | G9: 4124.5 | H9: 1290.8 | I9: 1213
A10: 1 | B10: 13-03 | C10: 83 | D10: 234-09 | E10: 8 | F10: Control
A11: 1 | B11: 13-03 | C11: 83 | D11: 322-09 | E11: 9 | F11: Control
A12: 1 | B12: 13-03 | C12: 83 | D12: 374-09 | E12: 10 | F12: Control
A13: 1 | B13: 14-02 | C13: 122 | D13: 162-09 | E13: 11 | F13: Control | G13: 361 | H13: 896 | I13: 452.3
A14: 1 | B14: 14-02 | C14: 122 | D14: 305-10 | E14: 12 | F14: Control | G14: 306 | H14: 1185 | I14: 777.9313
A15: 1 | B15: 14-02 | C15: 122 | D15: 280-10 | E15: 13 | F15: TLR7 | G15: 191 | H15: 324 | I15: 275.9488
A16: 1 | B16: 14-02 | C16: 122 | D16: 288-10 | E16: 14 | F16: TLR7 | G16: 234 | H16: 204 | I16: 339.7288
A17: 1 | B17: 14-02 | C17: 122 | D17: 344-10 | E17: 15 | F17: TLR7 | G17: 196 | H17: 3 | I17: 3
A18: 1 | B18: 14-02 | C18: 122 | D18: 293-09 | E18: 16 | F18: TLR7 | G18: 99 | H18: 1389 | I18: 362.8099
A19: 1 | B19: 14-02 | C19: 122 | D19: 295-10 | E19: 17 | F19: TLR7 | G19: 130 | H19: 329 | I19: 66.62798
A20: 1 | B20: 14-02 | C20: 122 | D20: 304-10 | E20: 18 | F20: TLR7 | G20: 1010 | H20: 608 | I20: 801.7266
A21: 1 | B21: 14-02 | C21: 125 | D21: 177-10 | E21: 19 | F21: TLR7 | G21: 3 | H21: 9 | I21: 3
A22: 1 | B22: 14-02 | C22: 125 | D22: 341-10 | E22: 20 | F22: TLR7 | G22: 230 | H22: 71 | I22: 301.5998
A23: 1 | B23: 14-02 | C23: 125 | D23: 412-10 | E23: 21 | F23: TLR7 | G23: 98 | H23: 140 | I23: 343.5055
G25: SIV DNA (10^6) before ART stop
G26: PBMC | H26: LNMC
A27: 2 | C27: 70 | D27: 5900 | E27: 5900 | F27: Control | G27: 3.0199517 | H27: 301.99517
A28: 2 | C28: 70 | D28: 5901 | E28: 5901 | F28: Control | G28: 575.43994 | H28: 7585.7758
A29: 2 | C29: 70 | D29: 5902 | E29: 5902 | F29: Control | G29: 3.0199517 | H29: 301.99517
A30: 2 | C30: 70 | D30: 5903 | E30: 5903 | F30: Control | G30: 223.87211 | H30: 2570.3958
A31: 2 | C31: 70 | D31: 5904 | E31: 5904 | F31: Control | G31: 3.0199517 | H31: 3.0199517
A32: 2 | C32: 70 | D32: 5905 | E32: 5905 | F32: Control | G32: 112.20185 | H32: 1318.2567
A33: 2 | C33: 70 | D33: 5906 | E33: 5906 | F33: Control | G33: 123.02688 | H33: 1621.8101
A34: 2 | C34: 70 | D34: 5907 | E34: 5907 | F34: Control | G34: 114.81536 | H34: 5011.8723
A35: 2 | C35: 70 | D35: 5908 | E35: 5908 | F35: Control | G35: 154.88166 | H35: 2187.7616
A36: 2 | C36: 70 | D36: 5891 | E36: 5891 | F36: TLR7
A37: 2 | C37: 70 | D37: 5892 | E37: 5892 | F37: TLR7 | G37: 3.0199517 | H37: 3.0199517
A38: 2 | C38: 70 | D38: 5893 | E38: 5893 | F38: TLR7 | G38: 181.97009 | H38: 1737.8008
A39: 2 | C39: 70 | D39: 5894 | E39: 5894 | F39: TLR7 | G39: 3.0199517 | H39: 4265.7952
A40: 2 | C40: 70 | D40: 5895 | E40: 5895 | F40: TLR7 | G40: 3.0199517 | H40: 912.01084
A41: 2 | C41: 70 | D41: 5896 | E41: 5896 | F41: TLR7 | G41: 3.0199517 | H41: 3.0199517
...

Sheet CD4
M2: Time (DPI) | N2: 595 | O2: 602 | P2: 609 | Q2: 616 | R2: 623 | S2: 630 | T2: 644 | U2: 651 | V2: 658 | W2: 665 | X2: 672
A3: Study | B3: Study Code | C3: Animal | D3: ID | E3: Treatment | F3: Initial CD4 | G3: Rebound Initial CD4 | H3: Rebound Rel Initial CD4 | I3: Rebound Nadir CD4 | J3: Rebound Rel Nadir CD4 | K3: Activated (CD69+) CD4 at ART stop | M3: Time (DPATI) | N3: =N2-$N$2 -> 0 | O3: =O2-$N$2 -> 7 | P3: =P2-$N$2 -> 14 | Q3: =Q2-$N$2 -> 21 | R3: =R2-$N$2 -> 28 | S3: =S2-$N$2 -> 35 | T3: =T2-$N$2 -> 49 | U3: =U2-$N$2 -> 56 | ... X3: =X2-$N$2 -> 77
A4: 1 | B4: 13-03 | C4: 156-08 | D4: 1 | E4: TLR7 | F4: 1760.56 | G4: =N4 -> 918.16 | H4: =G4/F4 -> 0.52151588 | I4: =MIN(N4:X4) -> 471.7 | J4: =I4/G4 -> 0.51374488 | K4: 0.544 | N4: 918.16 | O4: 1177.77 | P4: 785.56 | Q4: 571.59 | R4: 725.88 | S4: 652.38 | T4: 542.05 | U4: 471.7 | V4: 535.5 | W4: 688.6 | X4: 718.74
A5: 1 | B5: 13-03 | C5: 166-08 | D5: 2 | E5: TLR7 | F5: 737.1 | G5: =N5 -> 930.26 | H5: =G5/F5 -> 1.262054 | I5: =MIN(N5:X5) -> 876.15 | J5: =I5/G5 -> 0.94183347 | K5: 1.37 | N5: 930.26 | O5: 1353.34 | P5: 1297.99 | Q5: 876.15 | R5: 1072 | S5: 881.93 | T5: 886.83 | U5: 1219.04 | V5: 1281.28 | W5: 1161.27 | X5: 1012.68
A6: 1 | B6: 13-03 | C6: 280-09 | D6: 3 | E6: TLR7 | F6: 1555.7 | G6: =N6 -> 1591.65 | H6: =G6/F6 -> 1.0231086 | I6: =MIN(N6:X6) -> 904.5 | J6: =I6/G6 -> 0.5682782 | K6: 0.428 | N6: 1591.65 | O6: 1682.23 | P6: 1403.65 | Q6: 1254.92 | R6: 1290 | S6: 904.5 | T6: 1130.19 | U6: 1068.57 | V6: 1259.9 | W6: 1188.18 | X6: 1148.4
A7: 1 | B7: 13-03 | C7: 310-09 | D7: 4 | E7: TLR7 | F7: 1514.34 | G7: =N7 -> 904.75 | H7: =G7/F7 -> 0.597455 | I7: =MIN(N7:X7) -> 378.2 | J7: =I7/G7 -> 0.41801603 | K7: 0.655 | N7: 904.75 | O7: 1390.62 | P7: 994.68 | Q7: 784.8 | R7: 792.96 | S7: 483.6 | T7: 391.92 | U7: 631.8 | V7: 450.64 | W7: 378.2 | X7: 414.09
A8: 1 | B8: 13-03 | C8: 205-08 | D8: 5 | E8: Control | F8: 412.92 | G8: =N8 -> 472 | H8: =G8/F8 -> 1.1430786 | I8: =MIN(N8:X8) -> 472 | J8: =I8/G8 -> 1 | K8: 0.993 | N8: 472 | O8: 639.18 | P8: 651.78 | Q8: 747.72 | R8: 529.83 | S8: 572 | T8: 500.2 | U8: 522.5 | V8: 642.72 | W8: 565.47 | X8: 493.83
A9: 1 | B9: 13-03 | C9: 267-08 | D9: 6 | E9: Control | F9: 441 | G9: =N9 -> 587.52 | H9: =G9/F9 -> 1.3322449 | I9: =MIN(N9:X9) -> 492.68 | J9: =I9/G9 -> 0.83857571 | K9: 0.515 | N9: 587.52 | O9: 1306.03 | P9: 1084.2 | Q9: 944.58 | R9: 829.02 | S9: 492.68 | T9: 670.14 | U9: 710.48 | V9: 779.58 | W9: 911.52 | X9: 860.72
A10: 1 | B10: 13-03 | C10: 105-09 | D10: 7 | E10: Control | F10: 2907.2 | G10: =N10 -> 1199.7 | H10: =G10/F10 -> 0.41266511 | I10: =MIN(N10:X10) -> 559.12 | J10: =I10/G10 -> 0.46604985 | K10: 1.21 | N10: 1199.7 | O10: 1381.12 | P10: 1055.34 | Q10: 878.5 | R10: 734.41 | S10: 624.99 | T10: 712.5 | U10: 621 | V10: 565.63 | W10: 614.4 | X10: 559.12
A11: 1 | B11: 13-03 | C11: 234-09 | D11: 8 | E11: Control | F11: 1264.8 | I11: =MIN(N11:X11) -> 482.24 | O11: 927.14 | Q11: 871.2 | R11: 814.68 | S11: 518.91 | T11: 482.24
A12: 1 | B12: 13-03 | C12: 322-09 | D12: 9 | E12: Control | F12: 1232.84 | I12: =MIN(N12:X12) -> 678.08 | O12: 678.08 | Q12: 981.34 | R12: 1092 | S12: 1157.05 | T12: 1259.14
A13: 1 | B13: 13-03 | C13: 374-09 | D13: 10 | E13: Control | F13: 1270.24 | I13: =MIN(N13:X13) -> 1098.24 | O13: 1248.32 | Q13: 1098.24 | R13: 1140.8 | S13: 1114.18 | T13: 1183.64
M15: Time (DPI) | N15: 866 | O15: 873 | P15: 880 | Q15: 887 | R15: 894 | S15: 901 | T15: 908 | U15: 915 | V15: 922 | W15: 929 | X15: 936 | Y15: 947 | Z15: 950 | AA15: 957 | AB15: 964 | AC15: 971 | AD15: 978 | AE15: 985 | AF15: 992 | AG15: 999 | AH15: 1006 | AI15: 1013 | AJ15: 1020 | AK15: 1034 | AL15: 1041 | AM15: 1055 | AN15: 1062 | AO15: 1076
F16: Initial CD4 | G16: Rebound Initial CD4 | H16: Rebound Rel Initial CD4 | I16: Rebound Nadir CD4 | J16: Rebound Rel Nadir CD4 | M16: Time (DPATI) | N16: =N15-$N$15 -> 0 | O16: =O15-$N$15 -> 7 | P16: =P15-$N$15 -> 14 | Q16: =Q15-$N$15 -> 21 | R16: =R15-$N$15 -> 28 | S16: =S15-$N$15 -> 35 | T16: =T15-$N$15 -> 42 | U16: =U15-$N$15 -> 49 | ... AO16: =AO15-$N$15 -> 210
A17: 1 | B17: 14-02 | C17: 162-09 | D17: 11 | E17: Control | G17: =N17 -> 478.59 | H17: =G17/F17 -> #DIV/0! | I17: =MIN(N17:AB17) -> 263.78 | J17: =I17/G17 -> 0.5511607 | N17: 478.59 | O17: 314.86 | P17: 399.6 | Q17: 465.69 | R17: 386.34 | S17: 283.02 | T17: 349.25 | U17: 383.4 | V17: 398.64 | W17: 529.92 | X17: 323.64 | Y17: 263.78 | Z17: 301.92 | AA17: 408.24 | AB17: 494.73 | AC17: 408.8 | AD17: 318.92 | AE17: 355.74 | AF17: 477.52 | AG17: 224.07 | AH17: 392.01 | AJ17: 323.07 | AK17: 620.68 | AL17: 303.03 | AN17: 344.52 | AO17: 279.84
A18: 1 | B18: 14-02 | C18: 305-10 | D18: 12 | E18: Control | G18: =N18 -> 379.14 | H18: =G18/F18 -> #DIV/0! | I18: =MIN(N18:AB18) -> 379.14 | J18: =I18/G18 -> 1 | N18: 379.14 | O18: 461.9 | P18: 639.17 | Q18: 954.72 | R18: 843.2 | S18: 742.56 | T18: 929.1 | U18: 1097.4 | V18: 1059.38 | W18: 1158.24 | X18: 676.78 | Y18: 772.35 | Z18: 617.22 | AA18: 686.7 | AB18: 994.74 | AC18: 873.99 | AD18: 606.35 | AE18: 996.66 | AF18: 882.32 | AG18: 533.87 | AH18: 926.3 | AJ18: 651.82 | AK18: 1072.62 | AL18: 626.22 | AN18: 594.88 | AO18: 683.52
A19: 1 | B19: 14-02 | C19: 280-10 | D19: 13 | E19: TLR7 | G19: =N19 -> 526.11 | H19: =G19/F19 -> #DIV/0! | I19: =MIN(N19:AB19) -> 517.27 | J19: =I19/G19 -> 0.98319743 | N19: 526.11 | O19: 865.19 | P19: 688.16 | Q19: 919.6 | R19: 776 | S19: 826.11 | T19: 902.94 | U19: 709.8 | V19: 856.66 | W19: 746.72 | X19: 640.82 | Y19: 588.8 | Z19: 517.27 | AA19: 564.48 | AB19: 637.98 | AC19: 567.43 | AD19: 363.49 | AE19: 506.55 | AF19: 526.32 | AG19: 251.64 | AH19: 390.15 | AJ19: 388.3 | AK19: 301.4 | AL19: 212.524 | AN19: 203.728 | AO19: 240.45
A20: 1 | B20: 14-02 | C20: 288-10 | D20: 14 | E20: TLR7 | G20: =N20 -> 389.3 | H20: =G20/F20 -> #DIV/0! | I20: =MIN(N20:AB20) -> 279 | J20: =I20/G20 -> 0.71667095 | N20: 389.3 | O20: 464.43 | P20: 279 | Q20: 733.04 | R20: 751.68 | S20: 726.75 | T20: 734.82 | U20: 582.18 | V20: 622.16 | W20: 708.75 | X20: 502.25 | Y20: 508.41 | Z20: 588.9 | AA20: 541.44 | AB20: 738.15 | AC20: 502.99 | AD20: 501.37 | AE20: 558.25 | AF20: 894 | AG20: 205.2 | AH20: 756.92 | AJ20: 671.3 | AK20: 873.14 | AL20: 603.68 | AN20: 454.3 | AO20: 717.06
A21: 1 | B21: 14-02 | C21: 344-10 | D21: 15 | E21: TLR7 | G21: =N21 -> 670.32 | H21: =G21/F21 -> #DIV/0! | I21: =MIN(N21:AB21) -> 486.14 | J21: =I21/G21 -> 0.72523571 | N21: 670.32 | O21: 486.14 | P21: 537.88 | Q21: 973.18 | R21: 778 | S21: 1033.9 | T21: 1130.96 | U21: 780 | V21: 751.1 | W21: 811.96 | X21: 969.33 | Y21: 898.88 | Z21: 797.35 | AA21: 905.22 | AB21: 764.75 | AC21: 726.45 | AD21: 865.81 | AE21: 940.5 | AF21: 1367.46 | AG21: 1069.64 | AH21: 1012.42 | AJ21: 1017.27 | AK21: 978.12 | AL21: 892.44 | AN21: 1009.89 | AO21: 723.24
A22: 1 | B22: 14-02 | C22: 293-09 | D22: 16 | E22: TLR7 | G22: =N22 -> 477.4 | H22: =G22/F22 -> #DIV/0! | I22: =MIN(N22:AB22) -> 198 | J22: =I22/G22 -> 0.41474654 | N22: 477.4 | O22: 297.46 | P22: 394.24 | Q22: 444.8 | R22: 422.73 | S22: 348.25 | T22: 519.48 | U22: 198 | V22: 404.2 | W22: 328.64 | X22: 352.6 | Y22: 350.4 | Z22: 259.17 | AA22: 243.44 | AB22: 260.4 | AC22: 255.19 | AD22: 239.4 | AE22: 330.24 | AF22: 195.94 | AG22: 167.62 | AH22: 225.42 | AJ22: 232.869 | AK22: 229.026 | AL22: 197.37 | AN22: 101.661 | AO22: 96.6
A23: 1 | B23: 14-02 | C23: 295-10 | D23: 17 | E23: TLR7 | G23: =N23 -> 744.77 | H23: =G23/F23 -> #DIV/0! | I23: =MIN(N23:AB23) -> 522.69 | J23: =I23/G23 -> 0.70181398 | N23: 744.77 | O23: 522.69 | P23: 1210.56 | Q23: 836.16 | R23: 1126.44 | S23: 981.06 | T23: 1416.62 | U23: 1379.7 | V23: 1198.08 | W23: 1202.63 | X23: 1179.24 | Y23: 964.8 | Z23: 841.32 | AA23: 1330.62 | AB23: 1497.6 | AC23: 1036.94 | AD23: 931.41 | AE23: 1004.64 | AF23: 1121.61 | AG23: 611.82 | AH23: 1319.5 | AJ23: 1069.59 | AK23: 1453.96 | AL23: 801.36 | AN23: 859.56 | AO23: 1046.18
A24: 1 | B24: 14-02 | C24: 304-10 | D24: 18 | E24: TLR7 | G24: =N24 -> 660.8 | H24: =G24/F24 -> #DIV/0! | I24: =MIN(N24:AB24) -> 225.32 | J24: =I24/G24 -> 0.34098063 | N24: 660.8 | O24: 475.8 | P24: 641.2 | Q24: 672.6 | R24: 536.76 | S24: 298.12 | T24: 385.32 | U24: 316.52 | V24: 457.32 | W24: 521.85 | X24: 298 | Y24: 394 | Z24: 225.32 | AA24: 292.37 | AB24: 377.14 | AC24: 280.56 | AD24: 273.6 | AE24: 301.07 | AF24: 430.08 | AG24: 180.48 | AH24: 370.74 | AJ24: 214.2 | AK24: 434.16 | AL24: 337.55 | AN24: 167.64 | AO24: 200.6
A25: 1 | B25: 14-02 | C25: 177-10 | D25: 19 | E25: TLR7 | G25: =N25 -> 933.24 | H25: =G25/F25 -> #DIV/0! | I25: =MIN(N25:AB25) -> 627.15 | J25: =I25/G25 -> 0.67201363 | N25: 933.24 | O25: 1157 | P25: 1316.88 | Q25: 1200.54 | R25: 627.15 | S25: 1150.2 | T25: 1081.9 | U25: 1119.69 | V25: 1461.5 | W25: 1194.62 | X25: 1064.77 | Y25: 1045.28 | Z25: 1110.2 | AA25: 1051.56 | AB25: 1169.48 | AC25: 1298.12 | AD25: 997.92 | AE25: 1099.99 | AG25: 1118.84 | AI25: 1089.58 | AJ25: 1023.99 | AL25: 949.57 | AM25: 820.45
A26: 1 | B26: 14-02 | C26: 341-10 | D26: 20 | E26: TLR7 | G26: =N26 -> 582.83 | H26: =G26/F26 -> #DIV/0! | I26: =MIN(N26:AB26) -> 469.26 | J26: =I26/G26 -> 0.80514044 | N26: 582.83 | O26: 687.6 | P26: 554.8 | Q26: 802.23 | R26: 483.3 | S26: 469.26 | T26: 611.9 | U26: 516.36 | V26: 625.92 | W26: 621.92 | X26: 775.58 | Y26: 684.76 | Z26: 578.79 | AA26: 619.36 | AB26: 722.07 | AC26: 807.58 | AD26: 336.04 | AE26: 699 | AG26: 723.57 | AI26: 696.08 | AJ26: 495.52 | AL26: 485.52 | AM26: 328.75
A27: 1 | B27: 14-02 | C27: 412-10 | D27: 21 | E27: TLR7 | G27: =N27 -> 598.5 | H27: =G27/F27 -> #DIV/0! | I27: =MIN(N27:AB27) -> 350 | J27: =I27/G27 -> 0.58479532 | N27: 598.5 | O27: 607.6 | P27: 635.8 | Q27: 473.28 | R27: 667.17 | S27: 695.46 | T27: 707 | U27: 492.68 | V27: 603.9 | W27: 350 | X27: 445.06 | Y27: 435.6 | Z27: 431.43 | AA27: 436.88 | AB27: 575.7 | AC27: 530.75 | AD27: 351.48 | AE27: 660.1 | AG27: 710.64 | AI27: 710.6 | AJ27: 563.22 | AL27: 438.7 | AM27: 327.25

Sheet Immune
F1: Cellular immune breadth (# peptide subpools giving IFN-g+ ELISOPT)
A2: Study | B2: Study Code | C2: Study Wk | D2: Animal | E2: Treatment | F2: Gag | G2: Env | H2: Pol | I2: Total
A3: 2 | C3: 50 | D3: 5900 | E3: Control | F3: 1 | G3: 1 | H3: 1 | I3: 3 | L3: *Time of peak immunity
A4: 2 | C4: 50 | D4: 5901 | E4: Control | F4: 1 | G4: 1 | H4: 1 | I4: 3
A5: 2 | C5: 50 | D5: 5902 | E5: Control | F5: 1 | G5: 1 | H5: 1 | I5: 3
A6: 2 | C6: 50 | D6: 5903 | E6: Control | F6: 1 | G6: 1 | H6: 1 | I6: 3
A7: 2 | C7: 50 | D7: 5904 | E7: Control | F7: 1 | G7: 1 | H7: 1 | I7: 3
A8: 2 | C8: 50 | D8: 5905 | E8: Control | F8: 1 | G8: 1 | H8: 1 | I8: 3
A9: 2 | C9: 50 | D9: 5906 | E9: Control | F9: 1 | G9: 1 | H9: 1 | I9: 3
A10: 2 | C10: 50 | D10: 5907 | E10: Control | F10: 1 | G10: 1 | H10: 1 | I10: 3
A11: 2 | C11: 50 | D11: 5908 | E11: Control | F11: 1 | G11: 1 | H11: 1 | I11: 3
A12: 2 | C12: 50 | D12: 5891 | E12: TLR7
A13: 2 | C13: 50 | D13: 5892 | E13: TLR7 | F13: 1 | G13: 1 | H13: 1 | I13: 3
A14: 2 | C14: 50 | D14: 5893 | E14: TLR7 | F14: 1 | G14: 1 | H14: 1 | I14: 3
A15: 2 | C15: 50 | D15: 5894 | E15: TLR7 | F15: 1 | G15: 1 | H15: 1 | I15: 3
A16: 2 | C16: 50 | D16: 5895 | E16: TLR7 | F16: 1 | G16: 1 | H16: 1 | I16: 3
A17: 2 | C17: 50 | D17: 5896 | E17: TLR7 | F17: 1 | G17: 1 | H17: 1 | I17: 3
A18: 2 | C18: 50 | D18: 5897 | E18: TLR7 | F18: 1 | G18: 1 | H18: 1 | I18: 3
A19: 2 | C19: 50 | D19: 5898 | E19: TLR7 | F19: 1 | G19: 1 | H19: 1 | I19: 3
A20: 2 | C20: 50 | D20: 5899 | E20: TLR7 | F20: 1 | G20: 1 | H20: 1 | I20: 3
A21: 2 | C21: 50 | D21: 5872 | E21: Vac | F21: 3 | G21: 1 | H21: 2 | I21: 6
A22: 2 | C22: 50 | D22: 5873 | E22: Vac | F22: 3 | G22: 2 | H22: 2 | I22: 7
A23: 2 | C23: 50 | D23: 5874 | E23: Vac | F23: 2 | G23: 3 | H23: 0 | I23: 5
A24: 2 | C24: 50 | D24: 5875 | E24: Vac | F24: 11 | G24: 22 | H24: 22 | I24: 55
... A32: 2 | C32: 50 | D32: 5884 | E32: Vac+TLR7 | F32: 3 | G32: 1 | H32: 0 | I32: 4
A33: 2 | C33: 50 | D33: 5885 | E33: Vac+TLR7
A34: 2 | C34: 50 | D34: 5886 | E34: Vac+TLR7 | F34: 1 | G34: 2 | H34: 1 | I34: 4
A35: 2 | C35: 50 | D35: 5887 | E35: Vac+TLR7 | F35: 4 | G35: 2 | H35: 1 | I35: 7
A36: 2 | C36: 50 | D36: 5888 | E36: Vac+TLR7 | F36: 3 | G36: 3 | H36: 3 | I36: 9
A37: 2 | C37: 50 | D37: 5889 | E37: Vac+TLR7 | F37: 6 | G37: 4 | H37: 3 | I37: 13
A38: 2 | C38: 50 | D38: 5890 | E38: Vac+TLR7 | F38: 9 | G38: 12 | H38: 16 | I38: 37
A40: 2 | C40: 72 | D40: 5900 | E40: Control | F40: 2 | G40: 1 | H40: 0 | I40: 3 | L40: *Time of ART stop
A41: 2 | C41: 72 | D41: 5901 | E41: Control | F41: 1 | G41: 1 | H41: 0 | I41: 2
A42: 2 | C42: 72 | D42: 5902 | E42: Control | F42: 2 | G42: 0 | H42: 2 | I42: 4
A43: 2 | C43: 72 | D43: 5903 | E43: Control | F43: 0 | G43: 0 | H43: 0 | I43: 0
A44: 2 | C44: 72 | D44: 5904 | E44: Control | F44: 1 | G44: 0 | H44: 0 | I44: 1
A45: 2 | C45: 72 | D45: 5905 | E45: Control | F45: 0 | G45: 0 | H45: 0 | I45: 0
A46: 2 | C46: 72 | D46: 5906 | E46: Control | F46: 1 | G46: 0 | H46: 0 | I46: 1
A47: 2 | C47: 72 | D47: 5907 | E47: Control | F47: 2 | G47: 2 | H47: 3 | I47: 7
A48: 2 | C48: 72 | D48: 5908 | E48: Control | F48: 0 | G48: 0 | H48: 0 | I48: 0
...

Sheet Individual Parameters 1 2
C1: B | G1: L | K1: Np | O1: m | S1: p | W1: ta
A2: Study | B2: Animal ID | C2: SAEM | D2: mean | E2: mode | F2: std | G2: SAEM | H2: mean | I2: mode | J2: std | K2: SAEM | L2: mean | M2: mode | N2: std | O2: SAEM | P2: mean | Q2: mode | R2: std | S2: SAEM | T2: mean | U2: mode | V2: std | W2: SAEM | X2: mean | Y2: mode | Z2: std | AA2: TLR7 | AB2: Vac | AC2: Study | AD2: intTLR7study | AE2: intTLR7Vac
A3: 1 | B3: 1 | C3: 4.51432e-07 | D3: 4.70556e-07 | E3: 4.53874e-07 | F3: 3.70849e-08 | G3: 118.668 | H3: 122.22 | I3: 124.023 | J3: 14.3435 | K3: 40339.5 | L3: 60720.9 | M3: 31802.4 | N3: 32438.2 | O3: 38.8318 | P3: 40.3693 | Q3: 35.3549 | R3: 29.479 | S3: 2.01115 | T3: 2.77816 | U3: 1.73778 | V3: 1.21698 | W3: 1.57105 | X3: 1.80407 | Y3: 1.76397 | Z3: 0.4081 | AA3: 1 | AB3: 0 | AC3: 1 | AD3: 1 | AE3: 0
A4: 1 | B4: 2 | C4: 4.44946e-07 | D4: 4.53305e-07 | E4: 4.4731e-07 | F4: 2.82036e-08 | G4: 123.839 | H4: 106.474 | I4: 114.355 | J4: 12.3242 | K4: 99896.6 | L4: 86996.1 | M4: 62624.9 | N4: 51735 | O4: 128.707 | P4: 119.159 | Q4: 87.7368 | R4: 100.531 | S4: 1.75964 | T4: 1.50071 | U4: 1.25277 | V4: 0.83156 | W4: 1.76183 | X4: 1.38506 | Y4: 1.58756 | Z4: 0.367453 | AA4: 1 | AB4: 0 | AC4: 1 | AD4: 1 | AE4: 0
A5: 1 | B5: 3 | C5: 4.59161e-07 | D5: 4.49688e-07 | E5: 4.44887e-07 | F5: 3.68319e-08 | G5: 112.801 | H5: 114.054 | I5: 112.717 | J5: 13.3727 | K5: 171100 | L5: 141772 | M5: 152577 | N5: 73339 | O5: 492.7 | P5: 413.601 | Q5: 314.434 | R5: 374.148 | S5: 0.846414 | T5: 0.898942 | U5: 0.876904 | V5: 0.499595 | W5: 1.5509 | X5: 1.54045 | Y5: 1.50816 | Z5: 0.395431 | AA5: 1 | AB5: 0 | AC5: 1 | AD5: 1 | AE5: 0
A6: 1 | B6: 4 | C6: 4.43661e-07 | D6: 4.35658e-07 | E6: 4.45021e-07 | F6: 3.05255e-08 | G6: 106.803 | H6: 120.704 | I6: 112.684 | J6: 17.7031 | K6: 407044 | L6: 289100 | M6: 183863 | N6: 213276 | O6: 584.181 | P6: 493.154 | Q6: 293.001 | R6: 390.203 | S6: 1.18033 | T6: 0.960374 | U6: 0.849247 | V6: 0.502406 | W6: 1.3261 | X6: 1.60964 | Y6: 1.51992 | Z6: 0.463489 | AA6: 1 | AB6: 0 | AC6: 1 | AD6: 1 | AE6: 0
A7: 1 | B7: 5 | C7: 4.1822e-07 | D7: 4.17231e-07 | E7: 4.26862e-07 | F7: 2.87498e-08 | G7: 62.3794 | H7: 63.3082 | I7: 62.5458 | J7: 15.588 | K7: 230266 | L7: 216313 | M7: 177673 | N7: 152589 | O7: 907.19 | P7: 878.022 | Q7: 614.291 | R7: 1011.56 | S7: 0.788138 | T7: 0.824575 | U7: 0.791391 | V7: 0.442313 | W7: 0.747388 | X7: 0.794337 | Y7: 0.787838 | Z7: 0.598869 | AA7: 0 | AB7: 0 | AC7: 1 | AD7: 0 | AE7: 0
A8: 1 | B8: 6 | C8: 4.35578e-07 | D8: 4.4859e-07 | E8: 4.33162e-07 | F8: 3.26987e-08 | G8: 63.3722 | H8: 60.4172 | I8: 62.4734 | J8: 5.74467 | K8: 559339 | L8: 550044 | M8: 393674 | N8: 502761 | O8: 49.4165 | P8: 34.9196 | Q8: 22.9822 | R8: 35.9365 | S8: 0.705877 | T8: 0.749343 | U8: 0.733084 | V8: 0.353519 | W8: 0.109622 | X8: 0.103206 | Y8: 0.0929524 | Z8: 0.0607972 | AA8: 0 | AB8: 0 | AC8: 1 | AD8: 0 | AE8: 0
A9: 1 | B9: 7 | C9: 4.40474e-07 | D9: 4.48953e-07 | E9: 4.4661e-07 | F9: 3.27279e-08 | G9: 79.4222 | H9: 77.5753 | I9: 80.2374 | J9: 6.36605 | K9: 1179560 | L9: 1366330 | M9: 817674 | N9: 1677630 | O9: 7.21417 | P9: 12.786 | Q9: 6.43345 | R9: 22.4658 | S9: 0.584932 | T9: 0.522514 | U9: 0.543342 | V9: 0.306762 | W9: 0.586659 | X9: 0.599334 | Y9: 0.723901 | Z9: 0.253824 | AA9: 0 | AB9: 0 | AC9: 1 | AD9: 0 | AE9: 0
A10: 1 | B10: 8 | C10: 4.38583e-07 | D10: 4.32652e-07 | E10: 4.37069e-07 | F10: 3.12024e-08 | G10: 103.22 | H10: 98.4934 | I10: 97.9638 | J10: 11.1956 | K10: 675318 | L10: 1172480 | M10: 263041 | N10: 1766520 | O10: 2.56172 | P10: 4.20078 | Q10: 1.43913 | R10: 6.18026 | S10: 0.642303 | T10: 0.567766 | U10: 0.565394 | V10: 0.382636 | W10: 1.38647 | X10: 1.16587 | Y10: 1.23952 | Z10: 0.305286 | AA10: 0 | AB10: 0 | AC10: 1 | AD10: 0 | AE10: 0
A11: 1 | B11: 9 | C11: 4.29587e-07 | D11: 4.28712e-07 | E11: 4.31008e-07 | F11: 3.0037e-08 | G11: 64.7029 | H11: 64.2049 | I11: 63.854 | J11: 6.62636 | K11: 160279 | L11: 107806 | M11: 72519.6 | N11: 81659.5 | O11: 82.3589 | P11: 47.3078 | Q11: 26.5588 | R11: 51.3178 | S11: 1.17097 | T11: 1.35765 | U11: 1.22167 | V11: 0.873674 | W11: 0.132333 | X11: 0.119293 | Y11: 0.11718 | Z11: 0.0733016 | AA11: 0 | AB11: 0 | AC11: 1 | AD11: 0 | AE11: 0
A12: 1 | B12: 10 | C12: 4.4461e-07 | D12: 4.45263e-07 | E12: 4.40082e-07 | F12: 3.49648e-08 | G12: 72.572 | H12: 72.4299 | I12: 73.4717 | J12: 7.79068 | K12: 268511 | L12: 376367 | M12: 174434 | N12: 564028 | O12: 26.6504 | P12: 24.7269 | Q12: 20.6515 | R12: 24.4779 | S12: 0.829874 | T12: 0.872742 | U12: 0.725093 | V12: 0.408873 | W12: 0.159214 | X12: 0.151828 | Y12: 0.144752 | Z12: 0.0903884 | AA12: 0 | AB12: 0 | AC12: 1 | AD12: 0 | AE12: 0
A13: 1 | B13: 11 | C13: 4.47329e-07 | D13: 4.50102e-07 | E13: 4.50732e-07 | F13: 2.90979e-08 | G13: 86.7667 | H13: 75.0934 | I13: 82.7254 | J13: 7.82896 | K13: 31733.1 | L13: 38460.2 | M13: 22451.5 | N13: 16291.6 | O13: 8.54215 | P13: 4.70039 | Q13: 7.6632 | R13: 2.71453 | S13: 1.59182 | T13: 1.90995 | U13: 1.27111 | V13: 0.5799 | W13: 1.26105 | X13: 0.903322 | Y13: 1.19351 | Z13: 0.289345 | AA13: 0 | AB13: 0 | AC13: 1 | AD13: 0 | AE13: 0
A14: 1 | B14: 12 | C14: 4.54092e-07 | D14: 4.51665e-07 | E14: 4.47853e-07 | F14: 3.51874e-08 | G14: 75.5555 | H14: 75.327 | I14: 76.2953 | J14: 7.41014 | K14: 322210 | L14: 280839 | M14: 187879 | N14: 198809 | O14: 56.1111 | P14: 45.2576 | Q14: 21.9689 | R14: 72.3716 | S14: 0.937309 | T14: 1.02703 | U14: 0.858242 | V14: 0.603827 | W14: 0.39757 | X14: 0.406235 | Y14: 0.401547 | Z14: 0.205746 | AA14: 0 | AB14: 0 | AC14: 1 | AD14: 0 | AE14: 0
... A57: 2 | B57: 5890 | C57: 4.34599e-07 | D57: 4.38359e-07 | E57: 4.36758e-07 | F57: 3.22666e-08 | G57: 73.0405 | H57: 68.936 | I57: 69.0262 | J57: 10.7638 | K57: 2334.01 | L57: 2165.92 | M57: 1605.4 | N57: 1833.99 | O57: 10.432 | P57: 11.2899 | Q57: 10.5337 | R57: 5.96096 | S57: 1.368 | T57: 1.2787 | U57: 1.04339 | V57: 0.648713 | W57: 5.72127 | X57: 5.24335 | Y57: 4.81452 | Z57: 1.71422 | AA57: 1 | AB57: 1 | AC57: 0 | AD57: 0 | AE57: 1

Sheet Individual Parameters S3
C1: B | G1: L | K1: Np | O1: m | S1: p | W1: ta
A2: Study | B2: Animal ID | C2: SAEM | D2: mean | E2: mode | F2: std | G2: SAEM | H2: mean | I2: mode | J2: std | K2: SAEM | L2: mean | M2: mode | N2: std | O2: SAEM | P2: mean | Q2: mode | R2: std | S2: SAEM | T2: mean | U2: mode | V2: std | W2: SAEM | X2: mean | Y2: mode | Z2: std | AA2: TLR7 | AB2: Ab | AC2: intTLR7Ab
A3: 3 | B3: 1 | C3: 1.26426e-06 | D3: 1.22325e-06 | E3: 1.19568e-06 | F3: 2.13837e-07 | G3: 39.142 | H3: 39.0505 | I3: 39.0505 | J3: 0 | K3: 69010 | L3: 70891.7 | M3: 65320.6 | N3: 28586.2 | O3: 0.432628 | P3: 0.402013 | Q3: 0.181237 | R3: 0.801918 | S3: 3.64735 | T3: 3.61765 | U3: 3.61765 | V3: 0 | W3: 2.88819 | X3: 2.72134 | Y3: 2.69951 | Z3: 0.805783 | AA3: 0 | AB3: 0 | AC3: 0
A4: 3 | B4: 2 | C4: 9.79353e-07 | D4: 9.866e-07 | E4: 1.08279e-06 | F4: 2.39204e-07 | G4: 39.142 | H4: 39.0505 | I4: 39.0505 | J4: 0 | K4: 287409 | L4: 260394 | M4: 250077 | N4: 132255 | O4: 9.39729 | P4: 3.63845 | Q4: 0.966495 | R4: 9.05922 | S4: 3.64735 | T4: 3.61765 | U4: 3.61765 | V4: 0 | W4: 7.53371 | X4: 7.61544 | Y4: 7.04158 | Z4: 2.17544 | AA4: 0 | AB4: 0 | AC4: 0
A5: 3 | B5: 3 | C5: 1.00539e-06 | D5: 1.03586e-06 | E5: 1.01089e-06 | F5: 1.94887e-07 | G5: 39.142 | H5: 39.0505 | I5: 39.0505 | J5: 0 | K5: 39462.1 | L5: 41140 | M5: 38787.9 | N5: 14710.6 | O5: 0.811213 | P5: 0.989009 | Q5: 0.567369 | R5: 1.56996 | S5: 3.64735 | T5: 3.61765 | U5: 3.61765 | V5: 0 | W5: 2.60409 | X5: 2.69093 | Y5: 2.72116 | Z5: 0.978001 | AA5: 0 | AB5: 0 | AC5: 0
A6: 3 | B6: 4 | C6: 1.02491e-06 | D6: 1.05402e-06 | E6: 1.02617e-06 | F6: 2.19812e-07 | G6: 39.142 | H6: 39.0505 | I6: 39.0505 | J6: 0 | K6: 209653 | L6: 209025 | M6: 185665 | N6: 97941.6 | O6: 62.1958 | P6: 69.4303 | Q6: 42.0007 | R6: 103.636 | S6: 3.64735 | T6: 3.61765 | U6: 3.61765 | V6: 0 | W6: 2.62923 | X6: 2.78054 | Y6: 2.99906 | Z6: 0.981038 | AA6: 0 | AB6: 0 | AC6: 0
A7: 3 | B7: 5 | C7: 9.40082e-07 | D7: 9.37662e-07 | E7: 9.04696e-07 | F7: 2.08657e-07 | G7: 39.142 | H7: 39.0505 | I7: 39.0505 | J7: 0 | K7: 96475.4 | L7: 92871.8 | M7: 74817.7 | N7: 44464.6 | O7: 49.4224 | P7: 41.5561 | Q7: 9.5193 | R7: 69.4948 | S7: 3.64735 | T7: 3.61765 | U7: 3.61765 | V7: 0 | W7: 7.26417 | X7: 7.42938 | Y7: 8.49448 | Z7: 2.13082 | AA7: 0 | AB7: 0 | AC7: 0
A8: 3 | B8: 6 | C8: 9.88829e-07 | D8: 1.04321e-06 | E8: 1.04741e-06 | F8: 2.29197e-07 | G8: 39.142 | H8: 39.0505 | I8: 39.0505 | J8: 0 | K8: 68772 | L8: 65611.3 | M8: 60862.4 | N8: 26515.8 | O8: 13.3674 | P8: 13.5377 | Q8: 10.8562 | R8: 20.5552 | S8: 3.64735 | T8: 3.61765 | U8: 3.61765 | V8: 0 | W8: 1.47349 | X8: 1.60794 | Y8: 1.65692 | Z8: 0.628718 | AA8: 0 | AB8: 0 | AC8: 0
A9: 3 | B9: 7 | C9: 1.05995e-06 | D9: 9.54612e-07 | E9: 9.27044e-07 | F9: 2.17696e-07 | G9: 39.142 | H9: 39.0505 | I9: 39.0505 | J9: 0 | K9: 76789.4 | L9: 73361.2 | M9: 62625.4 | N9: 37206.1 | O9: 0.537249 | P9: 0.47053 | Q9: 0.0823792 | R9: 1.57309 | S9: 3.64735 | T9: 3.61765 | U9: 3.61765 | V9: 0 | W9: 12.5471 | X9: 11.2122 | Y9: 11.722 | Z9: 2.81801 | AA9: 0 | AB9: 0 | AC9: 0
A10: 3 | B10: 8 | C10: 9.71854e-07 | D10: 9.72165e-07 | E10: 9.65916e-07 | F10: 1.95595e-07 | G10: 39.142 | H10: 39.0505 | I10: 39.0505 | J10: 0 | K10: 49776.6 | L10: 53337.9 | M10: 47472.8 | N10: 21003.4 | O10: 3.89937 | P10: 3.57958 | Q10: 0.892237 | R10: 8.5754 | S10: 3.64735 | T10: 3.61765 | U10: 3.61765 | V10: 0 | W10: 4.19292 | X10: 4.15284 | Y10: 4.33169 | Z10: 1.2936 | AA10: 0 | AB10: 0 | AC10: 0
A11: 3 | B11: 9 | C11: 1.06726e-06 | D11: 1.07795e-06 | E11: 1.04428e-06 | F11: 1.87643e-07 | G11: 39.142 | H11: 39.0505 | I11: 39.0505 | J11: 0 | K11: 68766.2 | L11: 65162.2 | M11: 59353 | N11: 25769.9 | O11: 18.5164 | P11: 17.3554 | Q11: 10.0013 | R11: 25.5501 | S11: 3.64735 | T11: 3.61765 | U11: 3.61765 | V11: 0 | W11: 2.57777 | X11: 2.61934 | Y11: 2.6133 | Z11: 0.809388 | AA11: 0 | AB11: 0 | AC11: 0
A12: 3 | B12: 10 | C12: 9.74957e-07 | D12: 9.957e-07 | E12: 9.66045e-07 | F12: 2.14063e-07 | G12: 39.142 | H12: 39.0505 | I12: 39.0505 | J12: 0 | K12: 59354.8 | L12: 54733.5 | M12: 54064 | N12: 20798 | O12: 4.67884 | P12: 4.07926 | Q12: 3.11628 | R12: 6.84724 | S12: 3.64735 | T12: 3.61765 | U12: 3.61765 | V12: 0 | W12: 1.72893 | X12: 1.77318 | Y12: 1.72263 | Z12: 0.625153 | AA12: 0 | AB12: 0 | AC12: 0
A13: 3 | B13: 11 | C13: 1.05438e-06 | D13: 1.01381e-06 | E13: 9.5549e-07 | F13: 2.11855e-07 | G13: 39.142 | H13: 39.0505 | I13: 39.0505 | J13: 0 | K13: 142826 | L13: 125276 | M13: 113546 | N13: 63206.4 | O13: 0.129546 | P13: 0.0834777 | Q13: 0.0166121 | R13: 0.411187 | S13: 3.64735 | T13: 3.61765 | U13: 3.61765 | V13: 0 | W13: 12.3545 | X13: 12.0051 | Y13: 12.0405 | Z13: 2.65438 | AA13: 0 | AB13: 0 | AC13: 0
A14: 3 | B14: 12 | C14: 1.0457e-06 | D14: 1.07756e-06 | E14: 1.05198e-06 | F14: 2.2339e-07 | G14: 39.142 | H14: 39.0505 | I14: 39.0505 | J14: 0 | K14: 135315 | L14: 123847 | M14: 108730 | N14: 66736.3 | O14: 432.087 | P14: 416.502 | Q14: 332.312 | R14: 413.847 | S14: 3.64735 | T14: 3.61765 | U14: 3.61765 | V14: 0 | W14: 2.57586 | X14: 2.71259 | Y14: 2.62903 | Z14: 0.956519 | AA14: 1 | AB14: 0 | AC14: 0
... A46: 3 | B46: 44 | C46: 4.358e-07 | D46: 4.39747e-07 | E46: 4.42118e-07 | F46: 1.03391e-07 | G46: 39.142 | H46: 39.0505 | I46: 39.0505 | J46: 0 | K46: 11481 | L46: 11195.8 | M46: 9605.71 | N46: 7960.42 | O46: 18421.1 | P46: 12820.3 | Q46: 1449.85 | R46: 41220.4 | S46: 3.64735 | T46: 3.61765 | U46: 3.61765 | V46: 0 | W46: 4.78859 | X46: 5.42971 | Y46: 3.27116 | Z46: 5.45699 | AA46: 1 | AB46: 1 | AC46: 1

Sheet Reservoir correlations
A2: Study | B2: Animal ID | C2: ta_mean | D2: ta_mode | E2: SIV DNA PBMC | F2: SIV DNA LNMC | G2: SIV DNA GMMC
A3: ='Individual Parameters 1 2'!A3 -> 1 | B3: ='Individual Parameters 1 2'!B3 -> 1 | C3: ='Individual Parameters 1 2'!X3 -> 1.80407 | D3: ='Individual Parameters 1 2'!Y3 -> 1.76397 | E3: ='SIV DNA'!G3 -> 1205.3 | F3: ='SIV DNA'!H3 -> 650.4 | G3: ='SIV DNA'!I3 -> 3 | Q3: Spearman correlation: | S3: -0.42
A4: ='Individual Parameters 1 2'!A4 -> 1 | B4: ='Individual Parameters 1 2'!B4 -> 2 | C4: ='Individual Parameters 1 2'!X4 -> 1.38506 | D4: ='Individual Parameters 1 2'!Y4 -> 1.58756 | E4: ='SIV DNA'!G4 -> 1436.455 | F4: ='SIV DNA'!H4 -> 1050.5 | G4: ='SIV DNA'!I4 -> 3 | Q4: P value | S4: 3e-05
A5: ='Individual Parameters 1 2'!A5 -> 1 | B5: ='Individual Parameters 1 2'!B5 -> 3 | C5: ='Individual Parameters 1 2'!X5 -> 1.54045 | D5: ='Individual Parameters 1 2'!Y5 -> 1.50816 | E5: ='SIV DNA'!G5 -> 1174.3 | F5: ='SIV DNA'!H5 -> 1586.4 | G5: ='SIV DNA'!I5 -> 3
A6: ='Individual Parameters 1 2'!A6 -> 1 | B6: ='Individual Parameters 1 2'!B6 -> 4 | C6: ='Individual Parameters 1 2'!X6 -> 1.60964 | D6: ='Individual Parameters 1 2'!Y6 -> 1.51992 | E6: ='SIV DNA'!G6 -> 2457.584 | F6: ='SIV DNA'!H6 -> 1163.3 | G6: ='SIV DNA'!I6 -> 3
A7: ='Individual Parameters 1 2'!A7 -> 1 | B7: ='Individual Parameters 1 2'!B7 -> 5 | C7: ='Individual Parameters 1 2'!X7 -> 0.794337 | D7: ='Individual Parameters 1 2'!Y7 -> 0.787838 | E7: ='SIV DNA'!G7 -> 1107.235 | F7: ='SIV DNA'!H7 -> 1003.2 | G7: ='SIV DNA'!I7 -> 595
A8: ='Individual Parameters 1 2'!A8 -> 1 | B8: ='Individual Parameters 1 2'!B8 -> 6 | C8: ='Individual Parameters 1 2'!X8 -> 0.103206 | D8: ='Individual Parameters 1 2'!Y8 -> 0.0929524 | E8: ='SIV DNA'!G8 -> 8622.721 | F8: ='SIV DNA'!H8 -> 2506.208 | G8: ='SIV DNA'!I8 -> 596
A9: ='Individual Parameters 1 2'!A9 -> 1 | B9: ='Individual Parameters 1 2'!B9 -> 7 | C9: ='Individual Parameters 1 2'!X9 -> 0.599334 | D9: ='Individual Parameters 1 2'!Y9 -> 0.723901 | E9: ='SIV DNA'!G9 -> 4124.5 | F9: ='SIV DNA'!H9 -> 1290.8 | G9: ='SIV DNA'!I9 -> 1213
A10: ='Individual Parameters 1 2'!A10 -> 1 | B10: ='Individual Parameters 1 2'!B10 -> 8 | C10: ='Individual Parameters 1 2'!X10 -> 1.16587 | D10: ='Individual Parameters 1 2'!Y10 -> 1.23952
A11: ='Individual Parameters 1 2'!A11 -> 1 | B11: ='Individual Parameters 1 2'!B11 -> 9 | C11: ='Individual Parameters 1 2'!X11 -> 0.119293 | D11: ='Individual Parameters 1 2'!Y11 -> 0.11718
A12: ='Individual Parameters 1 2'!A12 -> 1 | B12: ='Individual Parameters 1 2'!B12 -> 10 | C12: ='Individual Parameters 1 2'!X12 -> 0.151828 | D12: ='Individual Parameters 1 2'!Y12 -> 0.144752
A13: ='Individual Parameters 1 2'!A13 -> 1 | B13: ='Individual Parameters 1 2'!B13 -> 11 | C13: ='Individual Parameters 1 2'!X13 -> 0.903322 | D13: ='Individual Parameters 1 2'!Y13 -> 1.19351 | E13: ='SIV DNA'!G13 -> 361 | F13: ='SIV DNA'!H13 -> 896 | G13: ='SIV DNA'!I13 -> 452.3
A14: ='Individual Parameters 1 2'!A14 -> 1 | B14: ='Individual Parameters 1 2'!B14 -> 12 | C14: ='Individual Parameters 1 2'!X14 -> 0.406235 | D14: ='Individual Parameters 1 2'!Y14 -> 0.401547 | E14: ='SIV DNA'!G14 -> 306 | F14: ='SIV DNA'!H14 -> 1185 | G14: ='SIV DNA'!I14 -> 777.9313
A15: ='Individual Parameters 1 2'!A15 -> 1 | B15: ='Individual Parameters 1 2'!B15 -> 13 | C15: ='Individual Parameters 1 2'!X15 -> 1.34929 | D15: ='Individual Parameters 1 2'!Y15 -> 1.39552 | E15: ='SIV DNA'!G15 -> 191 | F15: ='SIV DNA'!H15 -> 324 | G15: ='SIV DNA'!I15 -> 275.9488
A16: ='Individual Parameters 1 2'!A16 -> 1 | B16: ='Individual Parameters 1 2'!B16 -> 14 | C16: ='Individual Parameters 1 2'!X16 -> 1.14254 | D16: ='Individual Parameters 1 2'!Y16 -> 1.34434 | E16: ='SIV DNA'!G16 -> 234 | F16: ='SIV DNA'!H16 -> 204 | G16: ='SIV DNA'!I16 -> 339.7288
A17: ='Individual Parameters 1 2'!A17 -> 1 | B17: ='Individual Parameters 1 2'!B17 -> 15 | C17: ='Individual Parameters 1 2'!X17 -> 48.75 | D17: ='Individual Parameters 1 2'!Y17 -> 36.2452 | E17: ='SIV DNA'!G17 -> 196 | F17: ='SIV DNA'!H17 -> 3 | G17: ='SIV DNA'!I17 -> 3
A18: ='Individual Parameters 1 2'!A18 -> 1 | B18: ='Individual Parameters 1 2'!B18 -> 16 | C18: ='Individual Parameters 1 2'!X18 -> 3.42025 | D18: ='Individual Parameters 1 2'!Y18 -> 3.16763 | E18: ='SIV DNA'!G18 -> 99 | F18: ='SIV DNA'!H18 -> 1389 | G18: ='SIV DNA'!I18 -> 362.8099 | Q18: Spearman correlation: | S18: -0.44
A19: ='Individual Parameters 1 2'!A19 -> 1 | B19: ='Individual Parameters 1 2'!B19 -> 17 | C19: ='Individual Parameters 1 2'!X19 -> 1.08827 | D19: ='Individual Parameters 1 2'!Y19 -> 1.29281 | E19: ='SIV DNA'!G19 -> 130 | F19: ='SIV DNA'!H19 -> 329 | G19: ='SIV DNA'!I19 -> 66.62798 | Q19: P value | S19: 7e-06
A20: ='Individual Parameters 1 2'!A20 -> 1 | B20: ='Individual Parameters 1 2'!B20 -> 18 | C20: ='Individual Parameters 1 2'!X20 -> 1.15384 | D20: ='Individual Parameters 1 2'!Y20 -> 1.13123 | E20: ='SIV DNA'!G20 -> 1010 | F20: ='SIV DNA'!H20 -> 608 | G20: ='SIV DNA'!I20 -> 801.7266
A21: ='Individual Parameters 1 2'!A21 -> 1 | B21: ='Individual Parameters 1 2'!B21 -> 19 | C21: ='Individual Parameters 1 2'!X21 -> 42.854 | D21: ='Individual Parameters 1 2'!Y21 -> 29.1695 | E21: ='SIV DNA'!G21 -> 3 | F21: ='SIV DNA'!H21 -> 9 | G21: ='SIV DNA'!I21 -> 3
A22: ='Individual Parameters 1 2'!A22 -> 1 | B22: ='Individual Parameters 1 2'!B22 -> 20 | C22: ='Individual Parameters 1 2'!X22 -> 1.78399 | D22: ='Individual Parameters 1 2'!Y22 -> 1.89706 | E22: ='SIV DNA'!G22 -> 230 | F22: ='SIV DNA'!H22 -> 71 | G22: ='SIV DNA'!I22 -> 301.5998
A23: ='Individual Parameters 1 2'!A23 -> 1 | B23: ='Individual Parameters 1 2'!B23 -> 21 | C23: ='Individual Parameters 1 2'!X23 -> 1.11657 | D23: ='Individual Parameters 1 2'!Y23 -> 1.3083 | E23: ='SIV DNA'!G23 -> 98 | F23: ='SIV DNA'!H23 -> 140 | G23: ='SIV DNA'!I23 -> 343.5055
A24: ='Individual Parameters 1 2'!A24 -> 2 | B24: ='Individual Parameters 1 2'!B24 -> 5900 | C24: ='Individual Parameters 1 2'!X24 -> 0.625267 | D24: ='Individual Parameters 1 2'!Y24 -> 0.686525 | E24: ='SIV DNA'!G27 -> 3.0199517 | F24: ='SIV DNA'!H27 -> 301.99517
A25: ='Individual Parameters 1 2'!A25 -> 2 | B25: ='Individual Parameters 1 2'!B25 -> 5901 | C25: ='Individual Parameters 1 2'!X25 -> 0.271741 | D25: ='Individual Parameters 1 2'!Y25 -> 0.195079 | E25: ='SIV DNA'!G28 -> 575.43994 | F25: ='SIV DNA'!H28 -> 7585.7758
A26: ='Individual Parameters 1 2'!A26 -> 2 | B26: ='Individual Parameters 1 2'!B26 -> 5902 | C26: ='Individual Parameters 1 2'!X26 -> 0.24162 | D26: ='Individual Parameters 1 2'!Y26 -> 0.235281 | E26: ='SIV DNA'!G29 -> 3.0199517 | F26: ='SIV DNA'!H29 -> 301.99517
A27: ='Individual Parameters 1 2'!A27 -> 2 | B27: ='Individual Parameters 1 2'!B27 -> 5903 | C27: ='Individual Parameters 1 2'!X27 -> 0.279061 | D27: ='Individual Parameters 1 2'!Y27 -> 0.265032 | E27: ='SIV DNA'!G30 -> 223.87211 | F27: ='SIV DNA'!H30 -> 2570.3958
A28: ='Individual Parameters 1 2'!A28 -> 2 | B28: ='Individual Parameters 1 2'!B28 -> 5904 | C28: ='Individual Parameters 1 2'!X28 -> 0.53057 | D28: ='Individual Parameters 1 2'!Y28 -> 0.654917 | E28: ='SIV DNA'!G31 -> 3.0199517 | F28: ='SIV DNA'!H31 -> 3.0199517
A29: ='Individual Parameters 1 2'!A29 -> 2 | B29: ='Individual Parameters 1 2'!B29 -> 5905 | C29: ='Individual Parameters 1 2'!X29 -> 0.447746 | D29: ='Individual Parameters 1 2'!Y29 -> 0.519096 | E29: ='SIV DNA'!G32 -> 112.20185 | F29: ='SIV DNA'!H32 -> 1318.2567
A30: ='Individual Parameters 1 2'!A30 -> 2 | B30: ='Individual Parameters 1 2'!B30 -> 5906 | C30: ='Individual Parameters 1 2'!X30 -> 0.403096 | D30: ='Individual Parameters 1 2'!Y30 -> 0.359184 | E30: ='SIV DNA'!G33 -> 123.02688 | F30: ='SIV DNA'!H33 -> 1621.8101
A31: ='Individual Parameters 1 2'!A31 -> 2 | B31: ='Individual Parameters 1 2'!B31 -> 5907 | C31: ='Individual Parameters 1 2'!X31 -> 0.555919 | D31: ='Individual Parameters 1 2'!Y31 -> 0.686381 | E31: ='SIV DNA'!G34 -> 114.81536 | F31: ='SIV DNA'!H34 -> 5011.8723
A32: ='Individual Parameters 1 2'!A32 -> 2 | B32: ='Individual Parameters 1 2'!B32 -> 5908 | C32: ='Individual Parameters 1 2'!X32 -> 0.258065 | D32: ='Individual Parameters 1 2'!Y32 -> 0.338107 | E32: ='SIV DNA'!G35 -> 154.88166 | F32: ='SIV DNA'!H35 -> 2187.7616
A33: ='Individual Parameters 1 2'!A33 -> 2 | B33: ='Individual Parameters 1 2'!B33 -> 5892 | C33: ='Individual Parameters 1 2'!X33 -> 0.351977 | D33: ='Individual Parameters 1 2'!Y33 -> 0.40892 | E33: ='SIV DNA'!G37 -> 3.0199517 | F33: ='SIV DNA'!H37 -> 3.0199517 | Q33: Spearman correlation: | S33: -0.78
A34: ='Individual Parameters 1 2'!A34 -> 2 | B34: ='Individual Parameters 1 2'!B34 -> 5893 | C34: ='Individual Parameters 1 2'!X34 -> 0.562228 | D34: ='Individual Parameters 1 2'!Y34 -> 0.770262 | E34: ='SIV DNA'!G38 -> 181.97009 | F34: ='SIV DNA'!H38 -> 1737.8008 | Q34: P value | S34: 0.0001
A35: ='Individual Parameters 1 2'!A35 -> 2 | B35: ='Individual Parameters 1 2'!B35 -> 5894 | C35: ='Individual Parameters 1 2'!X35 -> 0.280574 | D35: ='Individual Parameters 1 2'!Y35 -> 0.271932 | E35: ='SIV DNA'!G39 -> 3.0199517 | F35: ='SIV DNA'!H39 -> 4265.7952
A36: ='Individual Parameters 1 2'!A36 -> 2 | B36: ='Individual Parameters 1 2'!B36 -> 5895 | C36: ='Individual Parameters 1 2'!X36 -> 0.344476 | D36: ='Individual Parameters 1 2'!Y36 -> 0.386822 | E36: ='SIV DNA'!G40 -> 3.0199517 | F36: ='SIV DNA'!H40 -> 912.01084
A37: ='Individual Parameters 1 2'!A37 -> 2 | B37: ='Individual Parameters 1 2'!B37 -> 5896 | C37: ='Individual Parameters 1 2'!X37 -> 0.257731 | D37: ='Individual Parameters 1 2'!Y37 -> 0.309495 | E37: ='SIV DNA'!G41 -> 3.0199517 | F37: ='SIV DNA'!H41 -> 3.0199517
A38: ='Individual Parameters 1 2'!A38 -> 2 | B38: ='Individual Parameters 1 2'!B38 -> 5897 | C38: ='Individual Parameters 1 2'!X38 -> 0.409126 | D38: ='Individual Parameters 1 2'!Y38 -> 0.564132 | E38: ='SIV DNA'!G42 -> 891.25094 | F38: ='SIV DNA'!H42 -> 3.0199517
A39: ='Individual Parameters 1 2'!A39 -> 2 | B39: ='Individual Parameters 1 2'!B39 -> 5898 | C39: ='Individual Parameters 1 2'!X39 -> 0.298011 | D39: ='Individual Parameters 1 2'!Y39 -> 0.22791 | E39: ='SIV DNA'!G43 -> 407.38028 | F39: ='SIV DNA'!H43 -> 3.0199517
A40: ='Individual Parameters 1 2'!A40 -> 2 | B40: ='Individual Parameters 1 2'!B40 -> 5899 | C40: ='Individual Parameters 1 2'!X40 -> 0.293589 | D40: ='Individual Parameters 1 2'!Y40 -> 0.203599 | E40: ='SIV DNA'!G44 -> 162.18101 | F40: ='SIV DNA'!H44 -> 2511.8864
A41: ='Individual Parameters 1 2'!A41 -> 2 | B41: ='Individual Parameters 1 2'!B41 -> 5872 | C41: ='Individual Parameters 1 2'!X41 -> 1.1566 | D41: ='Individual Parameters 1 2'!Y41 -> 1.37087 | E41: ='SIV DNA'!G45 -> 3.0199517 | F41: ='SIV DNA'!H45 -> 3.0199517
...

Sheet CD4 Correlations
A2: Study | B2: Animal ID | C2: L_mean | D2: L_mode | E2: ='CD4'!G3 -> Rebound Initial CD4 | F2: ='CD4'!H3 -> Rebound Rel Initial CD4 | G2: ='CD4'!K3 -> Activated (CD69+) CD4 at ART stop
A3: ='Individual Parameters 1 2'!A3 -> 1 | B3: ='Individual Parameters 1 2'!B3 -> 1 | C3: ='Individual Parameters 1 2'!H3 -> 122.22 | D3: ='Individual Parameters 1 2'!I3 -> 124.023 | E3: ='CD4'!G4 -> 918.16 | F3: ='CD4'!H4 -> 0.52151588 | G3: ='CD4'!K4 -> 0.544 | N3: Pearson correlation | O3: =CORREL(D3:D23,E3:E23) -> 0.23817708
A4: ='Individual Parameters 1 2'!A4 -> 1 | B4: ='Individual Parameters 1 2'!B4 -> 2 | C4: ='Individual Parameters 1 2'!H4 -> 106.474 | D4: ='Individual Parameters 1 2'!I4 -> 114.355 | E4: ='CD4'!G5 -> 930.26 | F4: ='CD4'!H5 -> 1.262054 | G4: ='CD4'!K5 -> 1.37 | N4: T | O4: =O3*SQRT(18)/SQRT(1-O3^2) -> 1.0404419
A5: ='Individual Parameters 1 2'!A5 -> 1 | B5: ='Individual Parameters 1 2'!B5 -> 3 | C5: ='Individual Parameters 1 2'!H5 -> 114.054 | D5: ='Individual Parameters 1 2'!I5 -> 112.717 | E5: ='CD4'!G6 -> 1591.65 | F5: ='CD4'!H6 -> 1.0231086 | G5: ='CD4'!K6 -> 0.428 | N5: p value | O5: =_xlfn.T.DIST.2T(O4,18) -> 0.31190906
A6: ='Individual Parameters 1 2'!A6 -> 1 | B6: ='Individual Parameters 1 2'!B6 -> 4 | C6: ='Individual Parameters 1 2'!H6 -> 120.704 | D6: ='Individual Parameters 1 2'!I6 -> 112.684 | E6: ='CD4'!G7 -> 904.75 | F6: ='CD4'!H7 -> 0.597455 | G6: ='CD4'!K7 -> 0.655
A7: ='Individual Parameters 1 2'!A7 -> 1 | B7: ='Individual Parameters 1 2'!B7 -> 5 | C7: ='Individual Parameters 1 2'!H7 -> 63.3082 | D7: ='Individual Parameters 1 2'!I7 -> 62.5458 | E7: ='CD4'!G8 -> 472 | F7: ='CD4'!H8 -> 1.1430786 | G7: ='CD4'!K8 -> 0.993
A8: ='Individual Parameters 1 2'!A8 -> 1 | B8: ='Individual Parameters 1 2'!B8 -> 6 | C8: ='Individual Parameters 1 2'!H8 -> 60.4172 | D8: ='Individual Parameters 1 2'!I8 -> 62.4734 | E8: ='CD4'!G9 -> 587.52 | F8: ='CD4'!H9 -> 1.3322449 | G8: ='CD4'!K9 -> 0.515
A9: ='Individual Parameters 1 2'!A9 -> 1 | B9: ='Individual Parameters 1 2'!B9 -> 7 | C9: ='Individual Parameters 1 2'!H9 -> 77.5753 | D9: ='Individual Parameters 1 2'!I9 -> 80.2374 | E9: ='CD4'!G10 -> 1199.7 | F9: ='CD4'!H10 -> 0.41266511 | G9: ='CD4'!K10 -> 1.21
A10: ='Individual Parameters 1 2'!A10 -> 1 | B10: ='Individual Parameters 1 2'!B10 -> 8 | C10: ='Individual Parameters 1 2'!H10 -> 98.4934 | D10: ='Individual Parameters 1 2'!I10 -> 97.9638
A11: ='Individual Parameters 1 2'!A11 -> 1 | B11: ='Individual Parameters 1 2'!B11 -> 9 | C11: ='Individual Parameters 1 2'!H11 -> 64.2049 | D11: ='Individual Parameters 1 2'!I11 -> 63.854
A12: ='Individual Parameters 1 2'!A12 -> 1 | B12: ='Individual Parameters 1 2'!B12 -> 10 | C12: ='Individual Parameters 1 2'!H12 -> 72.4299 | D12: ='Individual Parameters 1 2'!I12 -> 73.4717
A13: ='Individual Parameters 1 2'!A13 -> 1 | B13: ='Individual Parameters 1 2'!B13 -> 11 | C13: ='Individual Parameters 1 2'!H13 -> 75.0934 | D13: ='Individual Parameters 1 2'!I13 -> 82.7254 | E13: ='CD4'!G17 -> 478.59
A14: ='Individual Parameters 1 2'!A14 -> 1 | B14: ='Individual Parameters 1 2'!B14 -> 12 | C14: ='Individual Parameters 1 2'!H14 -> 75.327 | D14: ='Individual Parameters 1 2'!I14 -> 76.2953 | E14: ='CD4'!G18 -> 379.14
A15: ='Individual Parameters 1 2'!A15 -> 1 | B15: ='Individual Parameters 1 2'!B15 -> 13 | C15: ='Individual Parameters 1 2'!H15 -> 122.115 | D15: ='Individual Parameters 1 2'!I15 -> 121.35 | E15: ='CD4'!G19 -> 526.11
A16: ='Individual Parameters 1 2'!A16 -> 1 | B16: ='Individual Parameters 1 2'!B16 -> 14 | C16: ='Individual Parameters 1 2'!H16 -> 110.277 | D16: ='Individual Parameters 1 2'!I16 -> 113.37 | E16: ='CD4'!G20 -> 389.3
A17: ='Individual Parameters 1 2'!A17 -> 1 | B17: ='Individual Parameters 1 2'!B17 -> 15 | C17: ='Individual Parameters 1 2'!H17 -> 103.11 | D17: ='Individual Parameters 1 2'!I17 -> 100.208 | E17: ='CD4'!G21 -> 670.32
A18: ='Individual Parameters 1 2'!A18 -> 1 | B18: ='Individual Parameters 1 2'!B18 -> 16 | C18: ='Individual Parameters 1 2'!H18 -> 124.4 | D18: ='Individual Parameters 1 2'!I18 -> 115.58 | E18: ='CD4'!G22 -> 477.4
A19: ='Individual Parameters 1 2'!A19 -> 1 | B19: ='Individual Parameters 1 2'!B19 -> 17 | C19: ='Individual Parameters 1 2'!H19 -> 98.3143 | D19: ='Individual Parameters 1 2'!I19 -> 103.075 | E19: ='CD4'!G23 -> 744.77
A20: ='Individual Parameters 1 2'!A20 -> 1 | B20: ='Individual Parameters 1 2'!B20 -> 18 | C20: ='Individual Parameters 1 2'!H20 -> 110.48 | D20: ='Individual Parameters 1 2'!I20 -> 109.409 | E20: ='CD4'!G24 -> 660.8
A21: ='Individual Parameters 1 2'!A21 -> 1 | B21: ='Individual Parameters 1 2'!B21 -> 19 | C21: ='Individual Parameters 1 2'!H21 -> 105.432 | D21: ='Individual Parameters 1 2'!I21 -> 100.606 | E21: ='CD4'!G25 -> 933.24
A22: ='Individual Parameters 1 2'!A22 -> 1 | B22: ='Individual Parameters 1 2'!B22 -> 20 | C22: ='Individual Parameters 1 2'!H22 -> 102.113 | D22: ='Individual Parameters 1 2'!I22 -> 107.199 | E22: ='CD4'!G26 -> 582.83
A23: ='Individual Parameters 1 2'!A23 -> 1 | B23: ='Individual Parameters 1 2'!B23 -> 21 | C23: ='Individual Parameters 1 2'!H23 -> 100.325 | D23: ='Individual Parameters 1 2'!I23 -> 103.439 | E23: ='CD4'!G27 -> 598.5

Sheet Immune Correlations
A2: Study | B2: Animal ID | C2: NP_mode | D2: Log10(Np) | E2: m_mode | F2: p_mode | G2: Animal ID | H2: Treatments | I2: Total breadth peak | J2: Total breadth ART stop | K2: Gag breadth ART stop | L2: CD8+ % IFN-gamma | M2: Log10(CD8)
A3: ='Individual Parameters 1 2'!A24 -> 2 | B3: ='Individual Parameters 1 2'!B24 -> 5900 | C3: ='Individual Parameters 1 2'!M24 -> 1477630 | D3: =LOG10(C3) -> 6.1695657 | E3: ='Individual Parameters 1 2'!Q24 -> 249.669 | F3: ='Individual Parameters 1 2'!U24 -> 0.878651 | G3: =Immune!D3:D38 -> 5900 | H3: =Immune!E3 -> Control | J3: =Immune!I40 -> 3 | K3: =Immune!F40 -> 2 | L3: =Immune!F79 -> 0.329 | M3: =LOG10(L3) -> -0.4828041
A4: ='Individual Parameters 1 2'!A25 -> 2 | B4: ='Individual Parameters 1 2'!B25 -> 5901 | C4: ='Individual Parameters 1 2'!M25 -> 2813890 | D4: =LOG10(C4) -> 6.4493071 | E4: ='Individual Parameters 1 2'!Q25 -> 12.7456 | F4: ='Individual Parameters 1 2'!U25 -> 0.733213 | G4: =Immune!D4:D39 -> 5901 | H4: =Immune!E4 -> Control | J4: =Immune!I41 -> 2 | K4: =Immune!F41 -> 1 | L4: =Immune!F80 -> 0.0254 | M4: =LOG10(L4) -> -1.5951663
A5: ='Individual Parameters 1 2'!A26 -> 2 | B5: ='Individual Parameters 1 2'!B26 -> 5902 | C5: ='Individual Parameters 1 2'!M26 -> 577434 | D5: =LOG10(C5) -> 5.7615024 | E5: ='Individual Parameters 1 2'!Q26 -> 31.1277 | F5: ='Individual Parameters 1 2'!U26 -> 1.07536 | G5: =Immune!D5:D40 -> 5902 | H5: =Immune!E5 -> Control | J5: =Immune!I42 -> 4 | K5: =Immune!F42 -> 2 | L5: =Immune!F81 -> 0.118 | M5: =LOG10(L5) -> -0.92811799
A6: ='Individual Parameters 1 2'!A27 -> 2 | B6: ='Individual Parameters 1 2'!B27 -> 5903 | C6: ='Individual Parameters 1 2'!M27 -> 1131530 | D6: =LOG10(C6) -> 6.0536661 | E6: ='Individual Parameters 1 2'!Q27 -> 42.3547 | F6: ='Individual Parameters 1 2'!U27 -> 0.924179 | G6: =Immune!D6:D41 -> 5903 | H6: =Immune!E6 -> Control | J6: =Immune!I43 -> 0 | K6: =Immune!F43 -> 0 | L6: =Immune!F82 -> 0.0906 | M6: =LOG10(L6) -> -1.0428718
A7: ='Individual Parameters 1 2'!A28 -> 2 | B7: ='Individual Parameters 1 2'!B28 -> 5904 | C7: ='Individual Parameters 1 2'!M28 -> 1287110 | D7: =LOG10(C7) -> 6.1096157 | E7: ='Individual Parameters 1 2'!Q28 -> 29.2831 | F7: ='Individual Parameters 1 2'!U28 -> 0.885333 | G7: =Immune!D7:D42 -> 5904 | H7: =Immune!E7 -> Control | J7: =Immune!I44 -> 1 | K7: =Immune!F44 -> 1 | L7: =Immune!F83 -> 0.117 | M7: =LOG10(L7) -> -0.93181414
A8: ='Individual Parameters 1 2'!A29 -> 2 | B8: ='Individual Parameters 1 2'!B29 -> 5905 | C8: ='Individual Parameters 1 2'!M29 -> 1978400 | D8: =LOG10(C8) -> 6.2963141 | E8: ='Individual Parameters 1 2'!Q29 -> 37.1163 | F8: ='Individual Parameters 1 2'!U29 -> 0.808188 | G8: =Immune!D8:D43 -> 5905 | H8: =Immune!E8 -> Control | J8: =Immune!I45 -> 0 | K8: =Immune!F45 -> 0 | L8: =Immune!F84 -> 0.0415 | M8: =LOG10(L8) -> -1.3819519
A9: ='Individual Parameters 1 2'!A30 -> 2 | B9: ='Individual Parameters 1 2'!B30 -> 5906 | C9: ='Individual Parameters 1 2'!M30 -> 922012 | D9: =LOG10(C9) -> 5.9647366 | E9: ='Individual Parameters 1 2'!Q30 -> 228.916 | F9: ='Individual Parameters 1 2'!U30 -> 0.984917 | G9: =Immune!D9:D44 -> 5906 | H9: =Immune!E9 -> Control | J9: =Immune!I46 -> 1 | K9: =Immune!F46 -> 1 | L9: =Immune!F85 -> 0.176 | M9: =LOG10(L9) -> -0.75448733
A10: ='Individual Parameters 1 2'!A31 -> 2 | B10: ='Individual Parameters 1 2'!B31 -> 5907 | C10: ='Individual Parameters 1 2'!M31 -> 869058 | D10: =LOG10(C10) -> 5.9390488 | E10: ='Individual Parameters 1 2'!Q31 -> 64.6923 | F10: ='Individual Parameters 1 2'!U31 -> 0.985366 | G10: =Immune!D10:D45 -> 5907 | H10: =Immune!E10 -> Control | J10: =Immune!I47 -> 7 | K10: =Immune!F47 -> 2 | L10: =Immune!F86 -> 0.0277 | M10: =LOG10(L10) -> -1.5575202
A11: ='Individual Parameters 1 2'!A32 -> 2 | B11: ='Individual Parameters 1 2'!B32 -> 5908 | C11: ='Individual Parameters 1 2'!M32 -> 2054480 | D11: =LOG10(C11) -> 6.3127019 | E11: ='Individual Parameters 1 2'!Q32 -> 148.468 | F11: ='Individual Parameters 1 2'!U32 -> 0.81251 | G11: =Immune!D11:D46 -> 5908 | H11: =Immune!E11 -> Control | J11: =Immune!I48 -> 0 | K11: =Immune!F48 -> 0 | L11: =Immune!F87 -> 0
G12: =Immune!D12:D47 -> 5891 | H12: =Immune!E12 -> TLR7
A13: ='Individual Parameters 1 2'!A33 -> 2 | B13: ='Individual Parameters 1 2'!B33 -> 5892 | C13: ='Individual Parameters 1 2'!M33 -> 3175930 | D13: =LOG10(C13) -> 6.5018709 | E13: ='Individual Parameters 1 2'!Q33 -> 31.8686 | F13: ='Individual Parameters 1 2'!U33 -> 0.711452 | G13: =Immune!D13:D48 -> 5892 | H13: =Immune!E13 -> TLR7 | J13: =Immune!I50 -> 6 | K13: =Immune!F50 -> 1 | L13: =Immune!F89 -> 0.113 | M13: =LOG10(L13) -> -0.94692156
A14: ='Individual Parameters 1 2'!A34 -> 2 | B14: ='Individual Parameters 1 2'!B34 -> 5893 | C14: ='Individual Parameters 1 2'!M34 -> 3712400 | D14: =LOG10(C14) -> 6.5696548 | E14: ='Individual Parameters 1 2'!Q34 -> 13.1251 | F14: ='Individual Parameters 1 2'!U34 -> 0.689986 | G14: =Immune!D14:D49 -> 5893 | H14: =Immune!E14 -> TLR7 | J14: =Immune!I51 -> 1 | K14: =Immune!F51 -> 1 | L14: =Immune!F90 -> 0.339 | M14: =LOG10(L14) -> -0.4698003
A15: ='Individual Parameters 1 2'!A35 -> 2 | B15: ='Individual Parameters 1 2'!B35 -> 5894 | C15: ='Individual Parameters 1 2'!M35 -> 3151260 | D15: =LOG10(C15) -> 6.4984842 | E15: ='Individual Parameters 1 2'!Q35 -> 16.1394 | F15: ='Individual Parameters 1 2'!U35 -> 0.717705 | G15: =Immune!D15:D50 -> 5894 | H15: =Immune!E15 -> TLR7 | J15: =Immune!I52 -> 0 | K15: =Immune!F52 -> 0 | L15: =Immune!F91 -> 0.0972 | M15: =LOG10(L15) -> -1.0123337
A16: ='Individual Parameters 1 2'!A36 -> 2 | B16: ='Individual Parameters 1 2'!B36 -> 5895 | C16: ='Individual Parameters 1 2'!M36 -> 183139 | D16: =LOG10(C16) -> 5.2627808 | E16: ='Individual Parameters 1 2'!Q36 -> 13.2445 | F16: ='Individual Parameters 1 2'!U36 -> 1.57222 | G16: =Immune!D16:D51 -> 5895 | H16: =Immune!E16 -> TLR7 | J16: =Immune!I53 -> 0 | K16: =Immune!F53 -> 0 | L16: =Immune!F92 -> 0.018 | M16: =LOG10(L16) -> -1.7447275
A17: ='Individual Parameters 1 2'!A37 -> 2 | B17: ='Individual Parameters 1 2'!B37 -> 5896 | C17: ='Individual Parameters 1 2'!M37 -> 1430860 | D17: =LOG10(C17) -> 6.1555971 | E17: ='Individual Parameters 1 2'!Q37 -> 79.4358 | F17: ='Individual Parameters 1 2'!U37 -> 0.862697 | G17: =Immune!D17:D52 -> 5896 | H17: =Immune!E17 -> TLR7 | J17: =Immune!I54 -> 0 | K17: =Immune!F54 -> 0 | L17: =Immune!F93 -> 0.203 | M17: =LOG10(L17) -> -0.69250396 | O17: Correlation | P17: =PEARSON(D3:D38,I3:I38) -> -0.046994631 | T17: Correlation | U17: =PEARSON(E3:E38,I3:I38) -> -0.24792394
A18: ='Individual Parameters 1 2'!A38 -> 2 | B18: ='Individual Parameters 1 2'!B38 -> 5897 | C18: ='Individual Parameters 1 2'!M38 -> 719578 | D18: =LOG10(C18) -> 5.8570779 | E18: ='Individual Parameters 1 2'!Q38 -> 34.2592 | F18: ='Individual Parameters 1 2'!U38 -> 1.01903 | G18: =Immune!D18:D53 -> 5897 | H18: =Immune!E18 -> TLR7 | J18: =Immune!I55 -> 0 | K18: =Immune!F55 -> 0 | L18: =Immune!F94 -> 0.0474 | M18: =LOG10(L18) -> -1.3242217 | O18: T | P18: =P17*SQRT(33)/SQRT(1-P17^2) -> -0.27026221 | T18: T | U18: =U17*SQRT(33)/SQRT(1-U17^2) -> -1.4701122
A19: ='Individual Parameters 1 2'!A39 -> 2 | B19: ='Individual Parameters 1 2'!B39 -> 5898 | C19: ='Individual Parameters 1 2'!M39 -> 1178990 | D19: =LOG10(C19) -> 6.0715101 | E19: ='Individual Parameters 1 2'!Q39 -> 353.567 | F19: ='Individual Parameters 1 2'!U39 -> 0.929139 | G19: =Immune!D19:D54 -> 5898 | H19: =Immune!E19 -> TLR7 | J19: =Immune!I56 -> 1 | K19: =Immune!F56 -> 1 | L19: =Immune!F95 -> 0.0337 | M19: =LOG10(L19) -> -1.4723701 | O19: p value | P19: =_xlfn.T.DIST.2T(ABS(P18),33) -> 0.78864163 | T19: p value | U19: =_xlfn.T.DIST.2T(ABS(U18),33) -> 0.15100219
A20: ='Individual Parameters 1 2'!A40 -> 2 | B20: ='Individual Parameters 1 2'!B40 -> 5899 | C20: ='Individual Parameters 1 2'!M40 -> 1041790 | D20: =LOG10(C20) -> 6.0177802 | E20: ='Individual Parameters 1 2'!Q40 -> 372.331 | F20: ='Individual Parameters 1 2'!U40 -> 0.953633 | G20: =Immune!D20:D55 -> 5899 | H20: =Immune!E20 -> TLR7 | J20: =Immune!I57 -> 8 | K20: =Immune!F57 -> 3 | L20: =Immune!F96 -> 0.0916 | M20: =LOG10(L20) -> -1.0381045
A21: ='Individual Parameters 1 2'!A41 -> 2 | B21: ='Individual Parameters 1 2'!B41 -> 5872 | C21: ='Individual Parameters 1 2'!M41 -> 275432 | D21: =LOG10(C21) -> 5.4400144 | E21: ='Individual Parameters 1 2'!Q41 -> 204.484 | F21: ='Individual Parameters 1 2'!U41 -> 0.649216 | G21: =Immune!D21:D56 -> 5872 | H21: =Immune!E21 -> Vac | I21: =Immune!I21:I56 -> 6 | J21: =Immune!I58 -> 11 | K21: =Immune!F58 -> 5 | L21: =Immune!F97 -> 0.625 | M21: =LOG10(L21) -> -0.20411998
A22: ='Individual Parameters 1 2'!A42 -> 2 | B22: ='Individual Parameters 1 2'!B42 -> 5873 | C22: ='Individual Parameters 1 2'!M42 -> 178189 | D22: =LOG10(C22) -> 5.2508809 | E22: ='Individual Parameters 1 2'!Q42 -> 15.7337 | F22: ='Individual Parameters 1 2'!U42 -> 0.675029 | G22: =Immune!D22:D57 -> 5873 | H22: =Immune!E22 -> Vac | I22: =Immune!I22:I57 -> 7 | J22: =Immune!I59 -> 5 | K22: =Immune!F59 -> 3 | L22: =Immune!F98 -> 0.194 | M22: =LOG10(L22) -> -0.71219827
A23: ='Individual Parameters 1 2'!A43 -> 2 | B23: ='Individual Parameters 1 2'!B43 -> 5874 | C23: ='Individual Parameters 1 2'!M43 -> 17296.6 | D23: =LOG10(C23) -> 4.2379607 | E23: ='Individual Parameters 1 2'!Q43 -> 5.15069 | F23: ='Individual Parameters 1 2'!U43 -> 0.648814 | G23: =Immune!D23:D58 -> 5874 | H23: =Immune!E23 -> Vac | I23: =Immune!I23:I58 -> 5 | J23: =Immune!I60 -> 10 | K23: =Immune!F60 -> 4 | L23: =Immune!F99 -> 9.92 | M23: =LOG10(L23) -> 0.99651167
A24: ='Individual Parameters 1 2'!A44 -> 2 | B24: ='Individual Parameters 1 2'!B44 -> 5875 | C24: ='Individual Parameters 1 2'!M44 -> 155458 | D24: =LOG10(C24) -> 5.1916131 | E24: ='Individual Parameters 1 2'!Q44 -> 24.4924 | F24: ='Individual Parameters 1 2'!U44 -> 1.00034 | G24: =Immune!D24:D59 -> 5875 | H24: =Immune!E24 -> Vac | I24: =Immune!I24:I59 -> 55 | J24: =Immune!I61 -> 8 | K24: =Immune!F61 -> 3 | L24: =Immune!F100 -> 2.42 | M24: =LOG10(L24) -> 0.38381537
A25: ='Individual Parameters 1 2'!A45 -> 2 | B25: ='Individual Parameters 1 2'!B45 -> 5876 | C25: ='Individual Parameters 1 2'!M45 -> 109705 | D25: =LOG10(C25) -> 5.0402264 | E25: ='Individual Parameters 1 2'!Q45 -> 73.1015 | F25: ='Individual Parameters 1 2'!U45 -> 0.98601 | G25: =Immune!D25:D60 -> 5876 | H25: =Immune!E25 -> Vac | I25: =Immune!I25:I60 -> 10 | J25: =Immune!I62 -> 16 | K25: =Immune!F62 -> 6 | L25: =Immune!F101 -> 10 | M25: =LOG10(L25) -> 1
A26: ='Individual Parameters 1 2'!A46 -> 2 | B26: ='Individual Parameters 1 2'!B46 -> 5877 | C26: ='Individual Parameters 1 2'!M46 -> 17182.9 | D26: =LOG10(C26) -> 4.2350965 | E26: ='Individual Parameters 1 2'!Q46 -> 38.8019 | F26: ='Individual Parameters 1 2'!U46 -> 1.45107 | G26: =Immune!D26:D61 -> 5877 | H26: =Immune!E26 -> Vac | I26: =Immune!I26:I61 -> 18 | J26: =Immune!I63 -> 10 | K26: =Immune!F63 -> 4 | L26: =Immune!F102 -> 0.0374 | M26: =LOG10(L26) -> -1.4271284
A27: ='Individual Parameters 1 2'!A47 -> 2 | B27: ='Individual Parameters 1 2'!B47 -> 5879 | C27: ='Individual Parameters 1 2'!M47 -> 11955 | D27: =LOG10(C27) -> 4.0775496 | E27: ='Individual Parameters 1 2'!Q47 -> 6.80135 | F27: ='Individual Parameters 1 2'!U47 -> 1.06189 | G27: =Immune!D27:D62 -> 5879 | H27: =Immune!E27 -> Vac | I27: =Immune!I27:I62 -> 56 | J27: =Immune!I64 -> 10 | K27: =Immune!F64 -> 6 | L27: =Immune!F103 -> 0.766 | M27: =LOG10(L27) -> -0.11577123
A28: ='Individual Parameters 1 2'!A48 -> 2 | B28: ='Individual Parameters 1 2'!B48 -> 5880 | C28: ='Individual Parameters 1 2'!M48 -> 175144 | D28: =LOG10(C28) -> 5.2433953 | E28: ='Individual Parameters 1 2'!Q48 -> 134.053 | F28: ='Individual Parameters 1 2'!U48 -> 0.765376 | G28: =Immune!D28:D63 -> 5880 | H28: =Immune!E28 -> Vac | I28: =Immune!I28:I63 -> 18 | J28: =Immune!I65 -> 9 | K28: =Immune!F65 -> 3 | L28: =Immune!F104 -> 5.75 | M28: =LOG10(L28) -> 0.75966784
A29: ='Individual Parameters 1 2'!A49 -> 2 | B29: ='Individual Parameters 1 2'!B49 -> 5881 | C29: ='Individual Parameters 1 2'!M49 -> 251253 | D29: =LOG10(C29) -> 5.4001113 | E29: ='Individual Parameters 1 2'!Q49 -> 31.4073 | F29: ='Individual Parameters 1 2'!U49 -> 0.725779 | G29: =Immune!D29:D64 -> 5881 | H29: =Immune!E29 -> Vac | I29: =Immune!I29:I64 -> 14 | J29: =Immune!I66 -> 12 | K29: =Immune!F66 -> 5 | L29: =Immune!F105 -> 1.19 | M29: =LOG10(L29) -> 0.075546961
A30: ='Individual Parameters 1 2'!A50 -> 2 | B30: ='Individual Parameters 1 2'!B50 -> 5882 | C30: ='Individual Parameters 1 2'!M50 -> 12801.3 | D30: =LOG10(C30) -> 4.1072541 | E30: ='Individual Parameters 1 2'!Q50 -> 9.6793 | F30: ='Individual Parameters 1 2'!U50 -> 0.932295 | G30: =Immune!D30:D65 -> 5882 | H30: =Immune!E30 -> Vac+TLR7 | I30: =Immune!I30:I65 -> 18 | J30: =Immune!I67 -> 11 | K30: =Immune!F67 -> 5 | L30: =Immune!F106 -> 3.63 | M30: =LOG10(L30) -> 0.55990663
A31: ='Individual Parameters 1 2'!A51 -> 2 | B31: ='Individual Parameters 1 2'!B51 -> 5883 | C31: ='Individual Parameters 1 2'!M51 -> 668.004 | D31: =LOG10(C31) -> 2.8247791 | E31: ='Individual Parameters 1 2'!Q51 -> 7.89289 | F31: ='Individual Parameters 1 2'!U51 -> 0.726689 | G31: =Immune!D31:D66 -> 5883 | H31: =Immune!E31 -> Vac+TLR7 | I31: =Immune!I31:I66 -> 16 | J31: =Immune!I68 -> 9 | K31: =Immune!F68 -> 4 | L31: =Immune!F107 -> 4.61 | M31: =LOG10(L31) -> 0.66370093
A32: ='Individual Parameters 1 2'!A52 -> 2 | B32: ='Individual Parameters 1 2'!B52 -> 5884 | C32: ='Individual Parameters 1 2'!M52 -> 25844.4 | D32: =LOG10(C32) -> 4.4123665 | E32: ='Individual Parameters 1 2'!Q52 -> 52.0679 | F32: ='Individual Parameters 1 2'!U52 -> 0.591497 | G32: =Immune!D32:D67 -> 5884 | H32: =Immune!E32 -> Vac+TLR7 | I32: =Immune!I32:I67 -> 4 | J32: =Immune!I69 -> 25 | K32: =Immune!F69 -> 7 | L32: =Immune!F108 -> 1.26 | M32: =LOG10(L32) -> 0.10037055
G33: =Immune!D33:D68 -> 5885 | H33: =Immune!E33 -> Vac+TLR7
A34: ='Individual Parameters 1 2'!A53 -> 2 | B34: ='Individual Parameters 1 2'!B53 -> 5886 | C34: ='Individual Parameters 1 2'!M53 -> 1388.41 | D34: =LOG10(C34) -> 3.1425177 | E34: ='Individual Parameters 1 2'!Q53 -> 16.7963 | F34: ='Individual Parameters 1 2'!U53 -> 0.417438 | G34: =Immune!D34:D69 -> 5886 | H34: =Immune!E34 -> Vac+TLR7 | I34: =Immune!I34:I69 -> 4 | J34: =Immune!I71 -> 15 | K34: =Immune!F71 -> 5 | L34: =Immune!F110 -> 0.62 | M34: =LOG10(L34) -> -0.20760831
A35: ='Individual Parameters 1 2'!A54 -> 2 | B35: ='Individual Parameters 1 2'!B54 -> 5887 | C35: ='Individual Parameters 1 2'!M54 -> 11150.2 | D35: =LOG10(C35) -> 4.0472827 | E35: ='Individual Parameters 1 2'!Q54 -> 25.5759 | F35: ='Individual Parameters 1 2'!U54 -> 0.538374 | G35: =Immune!D35:D70 -> 5887 | H35: =Immune!E35 -> Vac+TLR7 | I35: =Immune!I35:I70 -> 7 | J35: =Immune!I72 -> 12 | K35: =Immune!F72 -> 5 | L35: =Immune!F111 -> 0.91 | M35: =LOG10(L35) -> -0.040958608 | Q35: Controls only
A36: ='Individual Parameters 1 2'!A55 -> 2 | B36: ='Individual Parameters 1 2'!B55 -> 5888 | C36: ='Individual Parameters 1 2'!M55 -> 21745.3 | D36: =LOG10(C36) -> 4.3373654 | E36: ='Individual Parameters 1 2'!Q55 -> 18.3791 | F36: ='Individual Parameters 1 2'!U55 -> 0.914467 | G36: =Immune!D36:D71 -> 5888 | H36: =Immune!E36 -> Vac+TLR7 | I36: =Immune!I36:I71 -> 9 | J36: =Immune!I73 -> 16 | K36: =Immune!F73 -> 6 | L36: =Immune!F112 -> 0.76 | M36: =LOG10(L36) -> -0.11918641 | O36: Correlation | P36: =PEARSON(D3:D38,J3:J38) -> -0.70238115 | Q36: =PEARSON(D3:D11,J3:J11) -> -0.49934879 | T36: Correlation | U36: =PEARSON(E3:E38,J3:J38) -> -0.18561417
